output/log.txt
[LIT-1][LIT_POOL] SELL 700 @ 100.0
[DRK-1][DARK_POOL] SELL 700 @ 99.9
[LIT-2][LIT_POOL] BUY 2000 @ 100.2
[LIT-2] [LIT_POOL] Filled: 700@100.0, Cumulative filled quantity: 700, Average fill price: 100
[LIT-1] [LIT_POOL] Filled: 700@100.0, Cumulative filled quantity: 700, Average fill price: 100
[LIT-1] [LIT_POOL] Completed Average fill price: 100
[DRK-2] [DARK_POOL] Filled: 700@99.9, Cumulative filled quantity: 700, Average fill price: 99.9
[DRK-1] [DARK_POOL] Filled: 700@99.9, Cumulative filled quantity: 700, Average fill price: 99.9
[DRK-1] [DARK_POOL] Completed Average fill price: 99.9
[DRK-2][DARK_POOL] BUY 1200 @ 100.2
[LIT-3][LIT_POOL] SELL 2500 @ 100.3
[DRK-3][DARK_POOL] SELL 400 @ 100.4
[LIT-4][LIT_POOL] BUY 2700 @ 100.1
[DRK-4][DARK_POOL] BUY 1000 @ 100.3
[LIT-5][LIT_POOL] SELL 2400 @ 100.4
[DRK-5][DARK_POOL] SELL 800 @ 100.4
[LIT-6][LIT_POOL] BUY 2300 @ 100.3
[LIT-6] [LIT_POOL] Filled: 2300@100.3, Cumulative filled quantity: 2300, Average fill price: 100.3
[LIT-6] [LIT_POOL] Completed Average fill price: 100.3
[LIT-3] [LIT_POOL] Filled: 2300@100.3, Cumulative filled quantity: 2300, Average fill price: 100.3
[DRK-6][DARK_POOL] BUY 1000 @ 100.3
[LIT-7][LIT_POOL] SELL 2400 @ 100.3
[DRK-7][DARK_POOL] SELL 1200 @ 100.5
[LIT-8][LIT_POOL] BUY 600 @ 100.4
[LIT-8] [LIT_POOL] Filled: 200@100.3, Cumulative filled quantity: 200, Average fill price: 100.3
[LIT-3] [LIT_POOL] Filled: 200@100.3, Cumulative filled quantity: 2500, Average fill price: 100.3
[LIT-3] [LIT_POOL] Completed Average fill price: 100.3
[LIT-8] [LIT_POOL] Filled: 400@100.3, Cumulative filled quantity: 600, Average fill price: 100.3
[LIT-8] [LIT_POOL] Completed Average fill price: 100.3
[LIT-7] [LIT_POOL] Filled: 400@100.3, Cumulative filled quantity: 400, Average fill price: 100.3
[DRK-8] [DARK_POOL] Filled: 400@100.4, Cumulative filled quantity: 400, Average fill price: 100.4
[DRK-8] [DARK_POOL] Completed Average fill price: 100.4
[DRK-3] [DARK_POOL] Filled: 400@100.4, Cumulative filled quantity: 400, Average fill price: 100.4
[DRK-3] [DARK_POOL] Completed Average fill price: 100.4
[DRK-8][DARK_POOL] BUY 400 @ 100.4
[LIT-9][LIT_POOL] SELL 2200 @ 100.7
[DRK-9][DARK_POOL] SELL 300 @ 100.8
[LIT-10][LIT_POOL] BUY 2300 @ 100.9
[LIT-10] [LIT_POOL] Filled: 2000@100.3, Cumulative filled quantity: 2000, Average fill price: 100.3
[LIT-7] [LIT_POOL] Filled: 2000@100.3, Cumulative filled quantity: 2400, Average fill price: 100.3
[LIT-7] [LIT_POOL] Completed Average fill price: 100.3
[LIT-10] [LIT_POOL] Filled: 300@100.4, Cumulative filled quantity: 2300, Average fill price: 100.31304347826087
[LIT-10] [LIT_POOL] Completed Average fill price: 100.31304347826087
[LIT-5] [LIT_POOL] Filled: 300@100.4, Cumulative filled quantity: 300, Average fill price: 100.4
[DRK-10] [DARK_POOL] Filled: 800@100.4, Cumulative filled quantity: 800, Average fill price: 100.4
[DRK-5] [DARK_POOL] Filled: 800@100.4, Cumulative filled quantity: 800, Average fill price: 100.4
[DRK-5] [DARK_POOL] Completed Average fill price: 100.4
[DRK-10] [DARK_POOL] Filled: 300@100.5, Cumulative filled quantity: 1100, Average fill price: 100.42727272727272
[DRK-10] [DARK_POOL] Completed Average fill price: 100.42727272727272
[DRK-7] [DARK_POOL] Filled: 300@100.5, Cumulative filled quantity: 300, Average fill price: 100.5
[DRK-10][DARK_POOL] BUY 1100 @ 101.0
[LIT-11][LIT_POOL] SELL 2900 @ 101.1
[DRK-11][DARK_POOL] SELL 700 @ 100.9
[LIT-12][LIT_POOL] BUY 1900 @ 100.9
[LIT-12] [LIT_POOL] Filled: 1900@100.9, Cumulative filled quantity: 1900, Average fill price: 100.9
[LIT-12] [LIT_POOL] Completed Average fill price: 100.9
[LIT-5] [LIT_POOL] Filled: 1900@100.9, Cumulative filled quantity: 2200, Average fill price: 100.83181818181818
[DRK-12] [DARK_POOL] Filled: 700@100.8, Cumulative filled quantity: 700, Average fill price: 100.8
[DRK-12] [DARK_POOL] Completed Average fill price: 100.8
[DRK-7] [DARK_POOL] Filled: 700@100.8, Cumulative filled quantity: 1000, Average fill price: 100.71
[DRK-12][DARK_POOL] BUY 700 @ 100.8
[LIT-13][LIT_POOL] SELL 1100 @ 100.9
[DRK-13][DARK_POOL] SELL 1200 @ 101.0
[LIT-14][LIT_POOL] BUY 800 @ 101.1
[LIT-14] [LIT_POOL] Filled: 200@101.1, Cumulative filled quantity: 200, Average fill price: 101.1
[LIT-5] [LIT_POOL] Filled: 200@101.1, Cumulative filled quantity: 2400, Average fill price: 100.85416666666667
[LIT-5] [LIT_POOL] Completed Average fill price: 100.85416666666667
[LIT-14] [LIT_POOL] Filled: 600@101.1, Cumulative filled quantity: 800, Average fill price: 101.1
[LIT-14] [LIT_POOL] Completed Average fill price: 101.1
[LIT-9] [LIT_POOL] Filled: 600@101.1, Cumulative filled quantity: 600, Average fill price: 101.1
[DRK-14] [DARK_POOL] Filled: 200@101.2, Cumulative filled quantity: 200, Average fill price: 101.2
[DRK-7] [DARK_POOL] Filled: 200@101.2, Cumulative filled quantity: 1200, Average fill price: 100.79166666666667
[DRK-7] [DARK_POOL] Completed Average fill price: 100.79166666666667
[DRK-14] [DARK_POOL] Filled: 200@101.2, Cumulative filled quantity: 400, Average fill price: 101.2
[DRK-14] [DARK_POOL] Completed Average fill price: 101.2
[DRK-9] [DARK_POOL] Filled: 200@101.2, Cumulative filled quantity: 200, Average fill price: 101.2
[DRK-14][DARK_POOL] BUY 400 @ 101.2
[LIT-15][LIT_POOL] SELL 1800 @ 101.0
[DRK-15][DARK_POOL] SELL 300 @ 101.1
[LIT-16][LIT_POOL] BUY 200 @ 101.0
[LIT-16] [LIT_POOL] Filled: 200@101.0, Cumulative filled quantity: 200, Average fill price: 101
[LIT-16] [LIT_POOL] Completed Average fill price: 101
[LIT-9] [LIT_POOL] Filled: 200@101.0, Cumulative filled quantity: 800, Average fill price: 101.075
[DRK-16] [DARK_POOL] Filled: 100@101.1, Cumulative filled quantity: 100, Average fill price: 101.1
[DRK-9] [DARK_POOL] Filled: 100@101.1, Cumulative filled quantity: 300, Average fill price: 101.16666666666667
[DRK-9] [DARK_POOL] Completed Average fill price: 101.16666666666667
[DRK-16] [DARK_POOL] Filled: 600@100.9, Cumulative filled quantity: 700, Average fill price: 100.92857142857143
[DRK-16] [DARK_POOL] Completed Average fill price: 100.92857142857143
[DRK-11] [DARK_POOL] Filled: 600@100.9, Cumulative filled quantity: 600, Average fill price: 100.9
[DRK-16][DARK_POOL] BUY 700 @ 101.1
[LIT-17][LIT_POOL] SELL 500 @ 100.9
[DRK-17][DARK_POOL] SELL 700 @ 101.0
[LIT-18][LIT_POOL] BUY 2500 @ 101.0
[LIT-18] [LIT_POOL] Filled: 1400@101.0, Cumulative filled quantity: 1400, Average fill price: 101
[LIT-9] [LIT_POOL] Filled: 1400@101.0, Cumulative filled quantity: 2200, Average fill price: 101.02727272727273
[LIT-9] [LIT_POOL] Completed Average fill price: 101.02727272727273
[LIT-18] [LIT_POOL] Filled: 1100@100.9, Cumulative filled quantity: 2500, Average fill price: 100.956
[LIT-18] [LIT_POOL] Completed Average fill price: 100.956
[LIT-13] [LIT_POOL] Filled: 1100@100.9, Cumulative filled quantity: 1100, Average fill price: 100.9
[LIT-13] [LIT_POOL] Completed Average fill price: 100.9
[DRK-18] [DARK_POOL] Filled: 100@100.9, Cumulative filled quantity: 100, Average fill price: 100.9
[DRK-11] [DARK_POOL] Filled: 100@100.9, Cumulative filled quantity: 700, Average fill price: 100.9
[DRK-11] [DARK_POOL] Completed Average fill price: 100.9
[DRK-18][DARK_POOL] BUY 1200 @ 100.9
[LIT-19][LIT_POOL] SELL 2300 @ 101.1
[DRK-19][DARK_POOL] SELL 100 @ 101.1
[LIT-20][LIT_POOL] BUY 2000 @ 100.9
[LIT-20] [LIT_POOL] Filled: 500@100.9, Cumulative filled quantity: 500, Average fill price: 100.9
[LIT-17] [LIT_POOL] Filled: 500@100.9, Cumulative filled quantity: 500, Average fill price: 100.9
[LIT-17] [LIT_POOL] Completed Average fill price: 100.9
[DRK-20][DARK_POOL] BUY 500 @ 100.9
[LIT-21][LIT_POOL] SELL 2300 @ 101.0
[DRK-18] [DARK_POOL] Filled: 300@100.9, Cumulative filled quantity: 400, Average fill price: 100.9
[DRK-21] [DARK_POOL] Filled: 300@100.9, Cumulative filled quantity: 300, Average fill price: 100.9
[DRK-21] [DARK_POOL] Completed Average fill price: 100.9
[DRK-21][DARK_POOL] SELL 300 @ 100.8
[LIT-22][LIT_POOL] BUY 1500 @ 100.8
[DRK-22][DARK_POOL] BUY 1100 @ 100.9
[LIT-23][LIT_POOL] SELL 400 @ 100.9
[LIT-20] [LIT_POOL] Filled: 400@100.9, Cumulative filled quantity: 900, Average fill price: 100.9
